-------------------------------------------------------------------------------
Test set: TestSuite
-------------------------------------------------------------------------------
Tests run: 12, Failures: 1, Errors: 0, Skipped: 0, Time elapsed: 249.9 s <<< FAILURE! -- in TestSuite
api.test.DDTests.DeleteUSer[testUser1](1) -- Time elapsed: 63.99 s <<< FAILURE!
org.awaitility.core.ConditionTimeoutException: api.test.DDTests$$Lambda/0x0000027c105d7268 expected the predicate to return <true> but was null within 1 minutes.
	at org.awaitility.core.ConditionAwaiter.await(ConditionAwaiter.java:167)
	at org.awaitility.core.AbstractHamcrestCondition.await(AbstractHamcrestCondition.java:86)
	at org.awaitility.core.ConditionFactory.until(ConditionFactory.java:985)
	at org.awaitility.core.ConditionFactory.until(ConditionFactory.java:691)
	at org.awaitility.core.ConditionFactory.until(ConditionFactory.java:708)
	at api.utilities.ApiUtils.retryApiCall(ApiUtils.java:16)
	at api.test.DDTests.DeleteUSer(DDTests.java:39)
	at java.base/jdk.internal.reflect.DirectMethodHandleAccessor.invoke(DirectMethodHandleAccessor.java:103)
	at java.base/java.lang.reflect.Method.invoke(Method.java:580)
	at org.testng.internal.invokers.MethodInvocationHelper.invokeMethod(MethodInvocationHelper.java:141)
	at org.testng.internal.invokers.TestInvoker.invokeMethod(TestInvoker.java:686)
	at org.testng.internal.invokers.TestInvoker.invokeTestMethod(TestInvoker.java:230)
	at org.testng.internal.invokers.MethodRunner.runInSequence(MethodRunner.java:63)
	at org.testng.internal.invokers.TestInvoker$MethodInvocationAgent.invoke(TestInvoker.java:992)
	at org.testng.internal.invokers.TestInvoker.invokeTestMethods(TestInvoker.java:203)
	at org.testng.internal.invokers.TestMethodWorker.invokeTestMethods(TestMethodWorker.java:154)
	at org.testng.internal.invokers.TestMethodWorker.run(TestMethodWorker.java:134)
	at java.base/java.util.ArrayList.forEach(ArrayList.java:1597)
	at org.testng.TestRunner.privateRun(TestRunner.java:739)
	at org.testng.TestRunner.run(TestRunner.java:614)
	at org.testng.SuiteRunner.runTest(SuiteRunner.java:421)
	at org.testng.SuiteRunner.runSequentially(SuiteRunner.java:413)
	at org.testng.SuiteRunner.privateRun(SuiteRunner.java:373)
	at org.testng.SuiteRunner.run(SuiteRunner.java:312)
	at org.testng.SuiteRunnerWorker.runSuite(SuiteRunnerWorker.java:52)
	at org.testng.SuiteRunnerWorker.run(SuiteRunnerWorker.java:95)
	at org.testng.TestNG.runSuitesSequentially(TestNG.java:1274)
	at org.testng.TestNG.runSuitesLocally(TestNG.java:1208)
	at org.testng.TestNG.runSuites(TestNG.java:1112)
	at org.testng.TestNG.run(TestNG.java:1079)
	at org.apache.maven.surefire.testng.TestNGExecutor.run(TestNGExecutor.java:308)
	at org.apache.maven.surefire.testng.TestNGXmlTestSuite.execute(TestNGXmlTestSuite.java:71)
	at org.apache.maven.surefire.testng.TestNGProvider.invoke(TestNGProvider.java:113)
	at org.apache.maven.surefire.booter.ForkedBooter.runSuitesInProcess(ForkedBooter.java:385)
	at org.apache.maven.surefire.booter.ForkedBooter.execute(ForkedBooter.java:162)
	at org.apache.maven.surefire.booter.ForkedBooter.run(ForkedBooter.java:507)
	at org.apache.maven.surefire.booter.ForkedBooter.main(ForkedBooter.java:495)
Caused by: java.util.concurrent.TimeoutException
	at java.base/java.util.concurrent.FutureTask.get(FutureTask.java:204)
	at org.awaitility.core.Uninterruptibles.getUninterruptibly(Uninterruptibles.java:101)
	at org.awaitility.core.Uninterruptibles.getUninterruptibly(Uninterruptibles.java:81)
	at org.awaitility.core.ConditionAwaiter.await(ConditionAwaiter.java:103)
	... 36 more

